<?xml version="1.0"?>
<robot name="quadruped_leg">


  <material name="red">
    <color rgba="1.0 0.0 0.0 1.0"/>
  </material>
 <material name="green">
    <color rgba="0.0 1.0 0.0 1.0"/>
</material>  
<material name="blue">
    <color rgba="0.0 0.0 1.0 1.0"/>
</material>
<material name="white">
    <color rgba="1 1.0 1.0 1.0"/>
</material>


  <link name="base_link">
    <visual>
      <geometry>
        <box size="0.3 0.1 0.02"/>
        <origin xyz = "0 0 0.01" rpy =" 0 0 1.0"/>
      </geometry>
      <material name="blue"/>

    </visual>

    <inertial>
         <origin xyz="0 0 0.01" rpy="0 0 1.0"/>
         <mass value="1"/>
         <inertia ixx="0.11"  ixy="0"  ixz="0.0" iyy= "0.04" iyz="0" izz="0.02" />
       </inertial>
     <collision>
        <origin xyz = "0 0 1.50" rpy="0 0 0"/>
        <geometry>
          <box size="0.3 0.1 0.02"/>
        </geometry>
    </collision>
  </link>


  
  <link name="thigh_link_front">
    <visual>
      <geometry>
        <cylinder length="0.045" radius="0.01"/>
      </geometry>
      <origin rpy="0 0 0" xyz="0 0 -0.0225"/>
    </visual>

    <inertial>
        <origin rpy="0 0 0" xyz="0 0 -0.0225"/>
        <mass value="1"/>
         <inertia ixx="0.11"  ixy="0"  ixz="0.0" iyy= "0.04" iyz="0" izz="0.02" />
      </inertial>
     <collision>
        <origin rpy="0 0 0" xyz="0 0 -0.0225"/>
        <geometry>
          <cylinder length="0.045" radius="0.01"/>
        </geometry>
    </collision> 
  </link>
  
  <joint name="elbow_joint_front" type="revolute">
    <axis xyz="0 1 0"/>
    <limit effort="10.0" lower="-0.39" upper="0.39" velocity="1.0"/>
    <parent link="base_link"/>
    <child link="thigh_link_front"/>
    <origin xyz="0.145 -0.045 -0.01"/>
  </joint>

 
  <link name="shank_link_front">
    <visual>
      <geometry>
        <cylinder length="0.05" radius="0.005"/>
      </geometry>
      <origin rpy="0 0 0" xyz="0 0 -0.025"/>
    </visual>

    <inertial>
        <origin rpy="0 0 0" xyz="0 0 -0.025"/>
        <mass value="1"/>
         <inertia ixx="0.11"  ixy="0"  ixz="0.0" iyy= "0.04" iyz="0" izz="0.02" />
      </inertial>
     <collision>
        <origin rpy="0 0 0" xyz="0 0 -0.025"/>
        <geometry>
          <cylinder length="0.05" radius="0.005"/>
        </geometry>
    </collision> 
  </link>
  
  <joint name="wrist_joint_front" type="revolute">
    <axis xyz="0 1 0"/>
    <limit effort="10.0" lower="-0.39" upper="0.40" velocity="1.0"/>
    <parent link="thigh_link_front"/>
    <child link="shank_link_front"/>
    <origin xyz="0 0 -0.045"/>
  </joint>





  
  <link name="thigh_link_front1">
    <visual>
      <geometry>
        <cylinder length="0.045" radius="0.01"/>
      </geometry>
      <origin rpy="0 0 0" xyz="0 0 -0.0225"/>
    </visual>
    <inertial>
        <origin rpy="0 0 0" xyz="0 0 -0.0225"/>
        <mass value="1"/>
         <inertia ixx="0.11"  ixy="0"  ixz="0.0" iyy= "0.04" iyz="0" izz="0.02" />
      </inertial>
     <collision>
        <origin rpy="0 0 0" xyz="0 0 -0.0225"/>
        <geometry>
          <cylinder length="0.045" radius="0.01"/>
        </geometry>
    </collision> 
  </link>
  


  <joint name="elbow_joint_front1" type="revolute">
    <axis xyz="0 1 0"/>
    <limit effort="10.0" lower="-1.57075" upper="1.57075" velocity="1.0"/>
    <parent link="base_link"/>
    <child link="thigh_link_front1"/>
     <origin xyz="0.145 0.045 -0.01"/>
  </joint>


  <link name="shank_link_front1">
    <visual>
      <geometry>
        <cylinder length="0.05" radius="0.005"/>
      </geometry>
      <origin rpy="0 0 0" xyz="0 0 -0.025"/>
    </visual>
    <inertial>
        <origin rpy="0 0 0" xyz="0 0 -0.025"/>
        <mass value="1"/>
         <inertia ixx="0.11"  ixy="0"  ixz="0.0" iyy= "0.04" iyz="0" izz="0.02" />
      </inertial>
     <collision>
        <origin rpy="0 0 0" xyz="0 0 -0.025"/>
        <geometry>
          <cylinder length="0.05" radius="0.005"/>
        </geometry>
    </collision> 

  </link>
  
  <joint name="wrist_joint_front1" type="revolute">
    <axis xyz="0 1 0"/>
    <limit effort="1.0" lower="-0.39" upper="0.39" velocity="1"/>
    <parent link="thigh_link_front1"/>
    <child link="shank_link_front1"/>
    <origin xyz="0 0 -0.045"/>
  </joint>


  <link name="thigh_link_back">
    <visual>
      <geometry>
        <cylinder length="0.045" radius="0.01"/>
      </geometry>
      <origin rpy="0 0 0" xyz="0 0 -0.0225"/>
    </visual>
    <inertial>
        <origin rpy="0 0 0" xyz="0 0 -0.0225"/>
        <mass value="1"/>
         <inertia ixx="0.11"  ixy="0"  ixz="0.0" iyy= "0.04" iyz="0" izz="0.02" />
      </inertial>
     <collision>
        <origin rpy="0 0 0" xyz="0 0 -0.0225"/>
        <geometry>
          <cylinder length="0.045" radius="0.01"/>
        </geometry>
    </collision>  
 
  </link>
  
  <joint name="elbow_joint_back" type="revolute">
    <axis xyz="0 1 0"/>
    <limit effort="10.0" lower="-0.39" upper="0.39"  velocity="1.0"/>
    <parent link="base_link"/>
    <child link="thigh_link_back"/>
    <origin xyz="-0.145 -0.045 -0.01"/>
  </joint>

 
  <link name="shank_link_back">
    <visual>
      <geometry>
        <cylinder length="0.05" radius="0.005"/>
      </geometry>
      <origin rpy="0 0 0" xyz="0 0 -0.025"/>
    </visual>

    <inertial>
        <origin rpy="0 0 0" xyz="0 0 -0.025"/>
        <mass value="1"/>
         <inertia ixx="0.11"  ixy="0"  ixz="0.0" iyy= "0.04" iyz="0" izz="0.02" />
      </inertial>
     <collision>
        <origin rpy="0 0 0" xyz="0 0 -0.025"/>
        <geometry>
          <cylinder length="0.05" radius="0.005"/>
        </geometry>
    </collision>  

  </link>
  <joint name="wrist_joint_back" type="revolute">
    <axis xyz="0 1 0"/>
    <limit effort="10.0"  lower="-0.39" upper="0.39" velocity="1.0"/>
    <parent link="thigh_link_back"/>
    <child link="shank_link_back"/>
    <origin xyz="0 0 -0.045"/>
  </joint>





  <link name="thigh_link_back1">
    <visual>
      <geometry>
        <cylinder length="0.045" radius="0.01"/>
      </geometry>
      <origin rpy="0 0 0" xyz="0 0 -0.0225"/>
    </visual>

    <inertial>
        <origin rpy="0 0 0" xyz="0 0 -0.0225"/>
        <mass value="1"/>
         <inertia ixx="0.11"  ixy="0"  ixz="0.0" iyy= "0.04" iyz="0" izz="0.02" />
      </inertial>
     <collision>
        <origin rpy="0 0 0" xyz="0 0 -0.0225"/>
        <geometry>
          <cylinder length="0.045" radius="0.01"/>
        </geometry>
    </collision>  

  </link>
  
  <joint name="elbow_joint_back1" type="revolute">
    <axis xyz="0 1 0"/>
    <limit effort="10.0" lower="-0.39" upper="0.39" velocity="1.0"/>
    <parent link="base_link"/>
    <child link="thigh_link_back1"/>
    <origin xyz="-0.145 0.045 -0.01"/>
  </joint>

 
  <link name="shank_link_back1">
    <visual>
      <geometry>
        <cylinder length="0.05" radius="0.005"/>
      </geometry>
      <origin rpy="0 0 0" xyz="0 0 -0.025"/>
    </visual>
    <inertial>
        <origin rpy="0 0 0" xyz="0 0 -0.025"/>
        <mass value="1"/>
         <inertia ixx="0.11"  ixy="0"  ixz="0.0" iyy= "0.04" iyz="0" izz="0.02" />
      </inertial>
     <collision>
        <origin rpy="0 0 0" xyz="0 0 -0.025"/>
        <geometry>
          <cylinder length="0.05" radius="0.005"/>
        </geometry>
    </collision>  
  </link>
   
  <joint name="wrist_joint_back1" type="revolute">
    <axis xyz="0 1 0"/>
    <limit effort="10.0" lower="-0.39" upper="0.39" velocity="1.0"/>
    <parent link="thigh_link_back1"/>
    <child link="shank_link_back1"/>
    <origin xyz="0 0 -0.045"/>
  </joint>












  <link name="body1_link">
    <visual>
      <geometry>
        <box size="0.03 0.03 0.02"/>
      </geometry>
      <origin xyz="0 0 0.01" rpy="0 0 0"/>
    </visual>
       <inertial>
         <origin xyz="0 0 0.5" rpy="0 0 0"/>
         <mass value="1"/>
         <inertia ixx="0.01"  ixy="0"  ixz="0" iyy= "0.01" iyz="0" izz="0.01" />

       </inertial>
     <collision>
        <origin xyz="0 0 0" rpy="0 0 0"/>
        <geometry>
          <cylinder length="0.035" radius="0.005"/>
        </geometry>
      </collision>

  </link>

  <joint name="body1_joint" type="fixed">
    <parent link="base_link"/>
    <child  link="body1_link"/>
    <origin xyz = "0.125 0 0.01"/>
  </joint>


 <joint name="body2_joint" type="revolute">
    <parent link="body1_link"/>
    <child  link="body2_link"/>
    <origin xyz="0 0 0.02" rpy="0 0 1.57"/>
    <limit lower="0.32" upper="0.7" effort="10" velocity="1"/>
  </joint>

  <link name="body2_link">
    <visual>
      <geometry>
        <box size="0.02 0.01 0.05"/>
      </geometry>
      <origin xyz="0 0 0.025" rpy="0 0 0"/>
    </visual>
    <inertial>
        <origin xyz="0 0 0.025" rpy="0 0 0"/>
        <mass value="1"/>
         <inertia ixx="0.01"  ixy="0"  ixz="0" iyy= "0.01" iyz="0" izz="0.01" />
      </inertial>
     <collision>
        <origin xyz="0 0 0.025" rpy="0 0 0"/>
        <geometry>
          <box size="0.02 0.01 0.05"/>
        </geometry>
    </collision>    
 
  </link>

   <joint name="body3_joint" type="revolute">
    <parent link="body2_link"/>
    <child  link="body3_link"/>
    <origin xyz="0 0 0.05" rpy="0 0 0"/>
    <limit lower="-1.5" upper="1.5" effort="10" velocity="1"/>
  </joint>
  <link name="body3_link">
    <visual>
      <geometry>
        <box size="0.01 0.01 0.1"/>
      </geometry>
      <origin xyz="0 0 0.05" rpy="0 0 0"/>
    </visual>

    <inertial>
        <origin xyz="0 0 0.05" rpy="0 0 0"/>
        <mass value="1"/>
         <inertia ixx="0.01"  ixy="0"  ixz="0" iyy= "0.01" iyz="0" izz="0.01" />
      </inertial>
     <collision>
        <origin xyz="0 0 0.05" rpy="0 0 0"/>
        <geometry>
          <box size="0.01 0.01 0.1"/>
        </geometry>
    </collision>    

  </link>


   <joint name="body4_joint" type="revolute">
    <parent link="body3_link"/>
    <child  link="body4_link"/>
    <origin xyz="0 0 0.1" rpy="0 0 0"/>
    <limit lower="-0.39" upper="0.39" effort="10.0" velocity="1"/>
  </joint>

  <link name="body4_link">
    <visual>
      <geometry>
        <box size="0.01 0.01 0.1"/>
      </geometry>
      <origin xyz="0 0 0.05" rpy="0 0 0"/>
    </visual>
    <inertial>
        <origin xyz="0 0 0.05" rpy="0 0 0"/>
        <mass value="1"/>
         <inertia ixx="0.01"  ixy="0"  ixz="0" iyy= "0.01" iyz="0" izz="0.01" />

      </inertial>
     <collision>
        <origin xyz="0 0 0.05" rpy="0 0 0"/>
        <geometry>
          <box size="0.01 0.01 0.1"/>
        </geometry>
    </collision>   
  </link> 


    <!-- <imu_sensor xyz="0.18 0 0.1"
                rpy="0 0 0" parent="body4_link"
                >
    </imu_sensor> -->
    
        <joint name="imu_sensor_joint" type="fixed">
            <axis xyz="0 0 1"/>
            <origin xyz="0.0 -0.008 0.095" rpy="0 0 0"/>
            <parent link="body4_link"/>
            <child link="camera_link"/>
        </joint>

        <link name="camera_link">
            <collision>
                <origin xyz="0 0 0" rpy="0 0 0"/>
                <geometry>
                    <box size="0.01 0.01 0.01"/>
                </geometry>
            </collision>
            <visual>
                <origin xyz="0 0 0" rpy="0 0 0"/>
                <geometry>
                    <box size="0.01 0.01 0.01"/>
                </geometry>
                <material name="blue"/>
            </visual>
            <inertial>
                <mass value="0.001"/>
                <origin xyz="0 0 0" rpy="0 0 0"/>
                <inertia ixx="0.00000015" ixy="0" ixz="0" iyy="0.00000015" iyz="0" izz="0.00000015"/>
            </inertial>
        </link>




  <transmission name="tran1">
    <type>transmission_interface/SimpleTransmission</type>
    <joint name="elbow_joint_front1">
      <hardwareInterface>hardware_interface/EffortJointInterface</hardwareInterface>
    </joint>
    <actuator name="motor1">
      <hardwareInterface>EffortJointInterface</hardwareInterface>
      <mechanicalReduction>1</mechanicalReduction>
    </actuator>
  </transmission>

  <transmission name="tran2">
    <type>transmission_interface/SimpleTransmission</type>
    <joint name="elbow_joint_front">
      <hardwareInterface>hardware_interface/EffortJointInterface</hardwareInterface>
    </joint>
    <actuator name="motor2">
      <hardwareInterface>EffortJointInterface</hardwareInterface>
      <mechanicalReduction>1</mechanicalReduction>
    </actuator>
  </transmission>

  <transmission name="tran3">
    <type>transmission_interface/SimpleTransmission</type>
    <joint name="wrist_joint_front">
      <hardwareInterface>hardware_interface/EffortJointInterface</hardwareInterface>
    </joint>
    <actuator name="motor3">
      <hardwareInterface>EffortJointInterface</hardwareInterface>
      <mechanicalReduction>1</mechanicalReduction>
    </actuator>
  </transmission>

  <transmission name="tran4">
    <type>transmission_interface/SimpleTransmission</type>
    <joint name="wrist_joint_front1">
      <hardwareInterface>hardware_interface/EffortJointInterface</hardwareInterface>
    </joint>
    <actuator name="motor4">
      <hardwareInterface>EffortJointInterface</hardwareInterface>
      <mechanicalReduction>1</mechanicalReduction>
    </actuator>
  </transmission>

  <transmission name="tran5">
    <type>transmission_interface/SimpleTransmission</type>
    <joint name="elbow_joint_back">
      <hardwareInterface>hardware_interface/EffortJointInterface</hardwareInterface>
    </joint>
    <actuator name="motor5">
      <hardwareInterface>EffortJointInterface</hardwareInterface>
      <mechanicalReduction>1</mechanicalReduction>
    </actuator>
  </transmission>

  <transmission name="tran6">
    <type>transmission_interface/SimpleTransmission</type>
    <joint name="wrist_joint_back">
      <hardwareInterface>hardware_interface/EffortJointInterface</hardwareInterface>
    </joint>
    <actuator name="motor6">
      <hardwareInterface>EffortJointInterface</hardwareInterface>
      <mechanicalReduction>1</mechanicalReduction>
    </actuator>
  </transmission>

  <transmission name="tran7">
    <type>transmission_interface/SimpleTransmission</type>
    <joint name="elbow_joint_back1">
      <hardwareInterface>hardware_interface/EffortJointInterface</hardwareInterface>
    </joint>
    <actuator name="motor7">
      <hardwareInterface>EffortJointInterface</hardwareInterface>
      <mechanicalReduction>1</mechanicalReduction>
    </actuator>
  </transmission>

  <transmission name="tran8">
    <type>transmission_interface/SimpleTransmission</type>
    <joint name="wrist_joint_back1">
      <hardwareInterface>hardware_interface/EffortJointInterface</hardwareInterface>
    </joint>
    <actuator name="motor8">
      <hardwareInterface>EffortJointInterface</hardwareInterface>
      <mechanicalReduction>1</mechanicalReduction>
    </actuator>
  </transmission>


<!-- 
 <transmission name="tran9">
    <type>transmission_interface/SimpleTransmission</type>
    <joint name="body1_joint">
      <hardwareInterface>hardware_interface/EffortJointInterface</hardwareInterface>
    </joint>
    <actuator name="motor9">
      <hardwareInterface>EffortJointInterface</hardwareInterface>
      <mechanicalReduction>1</mechanicalReduction>
    </actuator>
  </transmission> -->

  <transmission name="tran10">
    <type>transmission_interface/SimpleTransmission</type>
    <joint name="body2_joint">
      <hardwareInterface>hardware_interface/EffortJointInterface</hardwareInterface>
    </joint>
    <actuator name="motor10">
      <hardwareInterface>EffortJointInterface</hardwareInterface>
      <mechanicalReduction>1</mechanicalReduction>
    </actuator>
  </transmission>


   <transmission name="tran11">
    <type>transmission_interface/SimpleTransmission</type>
    <joint name="body3_joint">
      <hardwareInterface>hardware_interface/EffortJointInterface</hardwareInterface>
    </joint>
    <actuator name="motor11">
      <hardwareInterface>EffortJointInterface</hardwareInterface>
      <mechanicalReduction>1</mechanicalReduction>
    </actuator>
  </transmission>

  <transmission name="tran12">
    <type>transmission_interface/SimpleTransmission</type>
    <joint name="body4_joint">
      <hardwareInterface>hardware_interface/EffortJointInterface</hardwareInterface>
    </joint>
    <actuator name="motor12">
      <hardwareInterface>EffortJointInterface</hardwareInterface>
      <mechanicalReduction>1</mechanicalReduction>
    </actuator>
  </transmission>
<gazebo>
  <plugin name="gazebo_ros_control" filename="libgazebo_ros_control.so">
    <robotNamespace>/spot</robotNamespace>
  </plugin>
</gazebo>

  <!-- camera -->
  <gazebo reference="camera_link">
    <material>Gazebo/Yellow</material>
    <sensor type="camera" name="camera1">
      <update_rate>30.0</update_rate>
      <camera name="head">
        <horizontal_fov>1.3962634</horizontal_fov>
        <image>
          <width>800</width>
          <height>800</height>
          <format>R8G8B8</format>
        </image>
        <clip>
          <near>0.02</near>
          <far>300</far>
        </clip>
        <noise>
          <type>gaussian</type>
          <!-- Noise is sampled independently per pixel on each frame.
               That pixel's noise value is added to each of its color
               channels, which at that point lie in the range [0,1]. -->
          <mean>0.0</mean>
          <stddev>0.007</stddev>
        </noise>
      </camera>
      <plugin name="camera_controller" filename="libgazebo_ros_camera.so">
        <alwaysOn>true</alwaysOn>
        <updateRate>0.0</updateRate>
        <cameraName>spot/camera1</cameraName>
        <imageTopicName>image_raw</imageTopicName>
        <cameraInfoTopicName>camera_info</cameraInfoTopicName>
        <frameName>camera_link</frameName>
        <hackBaseline>0.07</hackBaseline>
        <distortionK1>0.0</distortionK1>
        <distortionK2>0.0</distortionK2>
        <distortionK3>0.0</distortionK3>
        <distortionT1>0.0</distortionT1>
        <distortionT2>0.0</distortionT2>
      </plugin>
    </sensor>
  </gazebo>


        <gazebo reference="body1_link">
            <gravity>true</gravity>
            <sensor name="imu_sensor" type="imu">
                <always_on>true</always_on>
                <update_rate>100</update_rate>
                <visualize>true</visualize>
                <topic>__default_topic__</topic>
                <plugin filename="libgazebo_ros_imu_sensor.so" name="imu_plugin">
                    <topicName>spot/imu_data</topicName>
                    <bodyName>imu_link</bodyName>
                    <updateRateHZ>10.0</updateRateHZ>
                    <gaussianNoise>0.0</gaussianNoise>
                    <xyzOffset>0 0 0</xyzOffset>
                    <rpyOffset>0 0 0</rpyOffset>
                    <frameName>body1_link</frameName>
                </plugin>
                <pose>0 0 0 0 0 0</pose>
            </sensor>
        </gazebo>
</robot>