<?xml version="1.0"?>
<robot name="quadruped_leg">


  <material name="red">
    <color rgba="1.0 0.0 0.0 1.0"/>
  </material>
 <material name="green">
    <color rgba="0.0 1.0 0.0 1.0"/>
</material>  
<material name="blue">
    <color rgba="0.0 0.0 1.0 1.0"/>
</material>
<material name="white">
    <color rgba="1 1.0 1.0 1.0"/>
</material>


  <link name="base_link">
    <visual>
      <geometry>
        <box size="0.3 0.1 0.02"/>
        <origin xyz = "0 0 1.50"/>
      </geometry>
      <material name="blue"/>

    </visual>
  </link>

  <link name="shoulder_link_front">
    <visual>
      <geometry>
        <cylinder length="0.035" radius="0.005"/>
      </geometry>
      <origin rpy="1.57075 0 0" xyz="0 -0.0175 0"/>
    </visual>
  </link>
  <joint name="shoulder_joint_front" type="fixed">
    <axis xyz="1 0 0"/> 
    <limit effort="1000.0" lower="-1.57075" upper="1.57075" velocity="0.5"/>
    <parent link="base_link"/>
    <child link="shoulder_link_front"/>
    <origin xyz="0.145 -0.015 -0.015"/>
  </joint>

  
  <link name="thigh_link_front">
    <visual>
      <geometry>
        <cylinder length="0.045" radius="0.01"/>
      </geometry>
      <origin rpy="0 0 0" xyz="0 0 -0.0225"/>
    </visual>
  </link>
  <joint name="elbow_joint_front" type="revolute">
    <axis xyz="0 1 0"/>
    <limit effort="1000.0" lower="-1.57075" upper="1.57075" velocity="0.5"/>
    <parent link="shoulder_link_front"/>
    <child link="thigh_link_front"/>
    <origin xyz="0 -0.025 -0.005"/>
  </joint>

 
  <link name="shank_link_front">
    <visual>
      <geometry>
        <cylinder length="0.05" radius="0.005"/>
      </geometry>
      <origin rpy="0 0 0" xyz="0 0 -0.025"/>
    </visual>
  </link>
  <joint name="wrist_joint_front" type="revolute">
    <axis xyz="0 1 0"/>
    <limit effort="1000.0" lower="-1.57075" upper="1.57075" velocity="0.5"/>
    <parent link="thigh_link_front"/>
    <child link="shank_link_front"/>
    <origin xyz="0 0 -0.045"/>
  </joint>



  <link name="shoulder_link_front1">
    <visual>
      <geometry>
        <cylinder length="0.035" radius="0.005"/>
      </geometry>
      <origin rpy="1.57075 0 0" xyz="0 -0.0175 0"/>
    </visual>
  </link>
  <joint name="shoulder_joint_front1" type="fixed">
    <axis xyz="1 0 0"/> 
    <limit effort="1000.0" lower="-1.57075" upper="1.57075" velocity="0.5"/>
    <parent link="base_link"/>
    <child link="shoulder_link_front1"/>
    <origin xyz="0.145 0.05 -0.015"/>
  </joint>

  
  <link name="thigh_link_front1">
    <visual>
      <geometry>
        <cylinder length="0.045" radius="0.01"/>
      </geometry>
      <origin rpy="0 0 0" xyz="0 0 -0.0225"/>
    </visual>
  </link>
  <joint name="elbow_joint_front1" type="revolute">
    <axis xyz="0 1 0"/>
    <limit effort="1000.0" lower="-1.57075" upper="1.57075" velocity="0.5"/>
    <parent link="shoulder_link_front1"/>
    <child link="thigh_link_front1"/>
    <origin xyz="0.0 -0.02 -0.005"/>
  </joint>

 
  <link name="shank_link_front1">
    <visual>
      <geometry>
        <cylinder length="0.05" radius="0.005"/>
      </geometry>
      <origin rpy="0 0 0" xyz="0 0 -0.025"/>
    </visual>
  </link>
  <joint name="wrist_joint_front1" type="revolute">
    <axis xyz="0 1 0"/>
    <limit effort="1000.0" lower="-1.57075" upper="1.57075" velocity="0.5"/>
    <parent link="thigh_link_front1"/>
    <child link="shank_link_front1"/>
    <origin xyz="0 0 -0.045"/>
  </joint>

  <link name="shoulder_link_back">
    <visual>
      <geometry>
        <cylinder length="0.035" radius="0.005"/>
      </geometry>
      <origin rpy="1.57075 0 0" xyz="0 -0.0175 0"/>
    </visual>
  </link>
  <joint name="shoulder_joint_back" type="fixed">
    <axis xyz="1 0 0"/>
    <limit effort="1000.0" lower="-1.57075" upper="1.57075" velocity="0.5"/>
    <parent link="base_link"/>
    <child link="shoulder_link_back"/>
    <origin xyz="-0.145 -0.015 -0.015"/>
  </joint>


  <link name="thigh_link_back">
    <visual>
      <geometry>
        <cylinder length="0.045" radius="0.01"/>
      </geometry>
      <origin rpy="0 0 0" xyz="0 0 -0.0225"/>
    </visual>
  </link>
  <joint name="elbow_joint_back" type="revolute">
    <axis xyz="0 1 0"/>
    <limit effort="1000.0" lower="-1.57075" upper="1.57075" velocity="0.5"/>
    <parent link="shoulder_link_back"/>
    <child link="thigh_link_back"/>
    <origin xyz="0 -0.025 -0.005"/>
  </joint>

 
  <link name="shank_link_back">
    <visual>
      <geometry>
        <cylinder length="0.05" radius="0.005"/>
      </geometry>
      <origin rpy="0 0 0" xyz="0 0 -0.025"/>
    </visual>
  </link>
  <joint name="wrist_joint_back" type="revolute">
    <axis xyz="0 1 0"/>
    <limit effort="1000.0" lower="-1.57075" upper="1.57075" velocity="0.5"/>
    <parent link="thigh_link_back"/>
    <child link="shank_link_back"/>
    <origin xyz="0 0 -0.045"/>
  </joint>


  <link name="shoulder_link_back1">
    <visual>
      <geometry>
        <cylinder length="0.035" radius="0.005"/>
      </geometry>
      <origin rpy="1.57075 0 0" xyz="0 -0.0175 0"/>
    </visual>
  </link>
  <joint name="shoulder_joint_back1" type="fixed">
    <axis xyz="1 0 0"/>
    <limit effort="1000.0" lower="-1.57075" upper="1.57075" velocity="0.5"/>
    <parent link="base_link"/>
    <child link="shoulder_link_back1"/>
    <origin xyz="-0.145 0.050 -0.015"/>
  </joint>



  <link name="thigh_link_back1">
    <visual>
      <geometry>
        <cylinder length="0.045" radius="0.01"/>
      </geometry>
      <origin rpy="0 0 0" xyz="0 0 -0.0225"/>
    </visual>
  </link>
  <joint name="elbow_joint_back1" type="revolute">
    <axis xyz="0 1 0"/>
    <limit effort="1000.0" lower="-1.57075" upper="1.57075" velocity="0.5"/>
    <parent link="shoulder_link_back1"/>
    <child link="thigh_link_back1"/>
    <origin xyz="0 -0.0125 -0.005"/>
  </joint>

 
  <link name="shank_link_back1">
    <visual>
      <geometry>
        <cylinder length="0.05" radius="0.005"/>
      </geometry>
      <origin rpy="0 0 0" xyz="0 0 -0.025"/>
    </visual>
  </link>
  <joint name="wrist_joint_back1" type="revolute">
    <axis xyz="0 1 0"/>
    <limit effort="1000.0" lower="-1.57075" upper="1.57075" velocity="0.5"/>
    <parent link="thigh_link_back1"/>
    <child link="shank_link_back1"/>
    <origin xyz="0 0 -0.045"/>
  </joint>



  <link name="body1_link">
    <visual>
      <geometry>
        <box size="0.03 0.03 0.02"/>
      </geometry>
      <origin xyz="0 0 0.01" rpy="0 0 0"/>
    </visual>
  </link>

  <joint name="body1_joint" type="prismatic">
    <parent link="base_link"/>
    <child  link="body1_link"/>
    <limit lower="-0.03" upper="0.0" effort="0" velocity="0"/>
    <origin xyz = "0.125 0 0.01"/>
  </joint>
 <joint name="body2_joint" type="revolute">
    <parent link="body1_link"/>
    <child  link="body2_link"/>
    <origin xyz="0 0 0.02" rpy="0 0 1.57"/>
    <limit lower="-0.523" upper="0.523" effort="0" velocity="0"/>
  </joint>
  <link name="body2_link">
    <visual>
      <geometry>
        <box size="0.02 0.01 0.05"/>
      </geometry>
      <origin xyz="0 0 0.025" rpy="0 0 0"/>
    </visual>
  </link>

   <joint name="body3_joint" type="revolute">
    <parent link="body2_link"/>
    <child  link="body3_link"/>
    <origin xyz="0 0 0.05" rpy="0 0 0"/>
    <limit lower="-1.5" upper="1.5" effort="0" velocity="0"/>
  </joint>
  <link name="body3_link">
    <visual>
      <geometry>
        <box size="0.01 0.01 0.1"/>
      </geometry>
      <origin xyz="0 0 0.05" rpy="0 0 0"/>
    </visual>
  </link>


   <joint name="body4_joint" type="revolute">
    <parent link="body3_link"/>
    <child  link="body4_link"/>
    <origin xyz="0 0 0.1" rpy="0 0 0"/>
    <limit lower="-1.5" upper="1.5" effort="0" velocity="0"/>
  </joint>
  <link name="body4_link">
    <visual>
      <geometry>
        <box size="0.01 0.01 0.1"/>
      </geometry>
      <origin xyz="0 0 0.05" rpy="0 0 0"/>
    </visual>
  </link>
</robot>